<?xml version="1.0" ?>
<!-- =================================================================================== -->
<!-- |    This document was autogenerated by xacro from /home/weifeng/Botkenstein/src/robot_function-pkg/urdf/BKRobot.urdf.xacro | -->
<!-- |    EDITING THIS FILE BY HAND IS NOT RECOMMENDED                                 | -->
<!-- =================================================================================== -->
<robot name="macroed">
    <!-- Defining the colors used in this robot -->
    <material name="Black">
        <color rgba="0 0 0 1" />
    </material>
    <material name="White">
        <color rgba="1 1 1 1" />
    </material>
    <material name="Blue">
        <color rgba="0 0 1 1" />
    </material>
    <material name="Red">
        <color rgba="1 0 0 1" />
    </material>
    <material name="Green">
        <color rgba="0 1 0 1" />
    </material>
    <!-- Constants -->
    <!-- /////////////////////////////////////   BASE LINK    ////////////////////////////////////////////// -->
    <link name="base_link">
        <visual>
            <origin rpy="0 0 0" xyz="0 0 0" />
            <geometry>
                <box size="0.02 0.02 0.001" />
            </geometry>
            <material name="White" />
        </visual>
    </link>
    <joint name="joint1" type="revolute">
        <parent link="base_link" />
        <child link="link1" />
        <origin rpy="0 0 0" xyz="0 0 0" />
        <axis xyz="0 0 1" />
        <limit effort="300" lower="-2.96" upper="2.96" velocity="1" />
        <dynamics damping="50" friction="1" />
    </joint>
    <!-- /////////////////////////////////////   LINK1  ////////////////////////////////////////////// -->
    <link name="link1">
        <visual>
            <origin rpy="0 -0.49680755172305 0" xyz="-0.0225 0 0.0415 " />
            <geometry>
                <cylinder length="0.094414" radius="0.01" />
            </geometry>
            <material name="Blue" />
        </visual>
        <inertial>
            <mass value="1" />
            <inertia ixx="1.0" ixy="0.0" ixz="0.0" iyy="0.5" iyz="0.0" izz="1.0" />
        </inertial>
    </link>
    <joint name="joint2" type="revolute">
        <parent link="link1" />
        <child link="link2" />
        <origin rpy="0 0 0" xyz="-0.045 0 0.083" />
        <axis xyz="0 1 0" />
        <limit effort="300" lower="-2.96" upper="2.96" velocity="1" />
        <dynamics damping="50" friction="1" />
    </joint>
    <!-- /////////////////////////////////////   LINK2  ////////////////////////////////////////////// -->
    <link name="link2">
        <visual>
            <origin rpy="0 0 0" xyz="0 0 0.0525" />
            <geometry>
                <cylinder length="0.105" radius="0.01" />
            </geometry>
            <material name="Red" />
        </visual>
        <inertial>
            <mass value="1" />
            <inertia ixx="1.0" ixy="0.0" ixz="0.0" iyy="0.5" iyz="0.0" izz="1.0" />
        </inertial>
    </link>
    <joint name="joint3" type="revolute">
        <parent link="link2" />
        <child link="link3" />
        <origin rpy="0 0 0" xyz="0 0  0.105" />
        <axis xyz="0 1 0" />
        <limit effort="300" lower="-2.96" upper="2.96" velocity="1" />
        <dynamics damping="50" friction="1" />
    </joint>
    <!-- /////////////////////////////////////   LINK3  ////////////////////////////////////////////// -->
    <link name="link3">
        <visual>
            <origin rpy="0 -1.2571770510508702 0" xyz="-0.0185 0 0.006" />
            <geometry>
                <cylinder length="0.0388973006776" radius="0.01" />
            </geometry>
            <material name="Blue" />
        </visual>
        <inertial>
            <mass value="1" />
            <inertia ixx="1.0" ixy="0.0" ixz="0.0" iyy="0.5" iyz="0.0" izz="1.0" />
        </inertial>
    </link>
    <joint name="joint4" type="revolute">
        <parent link="link3" />
        <child link="link4" />
        <origin rpy="0 0 0" xyz="-0.037 0 0.012" />
        <axis xyz="1 0 0" />
        <limit effort="300" lower="-2.96" upper="2.96" velocity="1" />
        <dynamics damping="50" friction="1" />
    </joint>
    <!-- /////////////////////////////////////   LINK4  ////////////////////////////////////////////// -->
    <link name="link4">
        <visual>
            <origin rpy="0 0 0" xyz="-0.07625 0 0" />
            <geometry>
                <box size="0.1525 0.02 0.02" />
            </geometry>
            <material name="Red" />
        </visual>
        <inertial>
            <mass value="1" />
            <inertia ixx="1.0" ixy="0.0" ixz="0.0" iyy="0.5" iyz="0.0" izz="1.0" />
        </inertial>
    </link>
    <joint name="joint5" type="revolute">
        <parent link="link4" />
        <child link="link5" />
        <origin rpy="0 0 0" xyz="-0.1525 0 0" />
        <axis xyz="0 1 0" />
        <limit effort="300" lower="-2.96" upper="2.96" velocity="1" />
        <dynamics damping="50" friction="1" />
    </joint>
    <!-- /////////////////////////////////////   LINK5  ////////////////////////////////////////////// -->
    <link name="link5">
        <visual>
            <origin rpy="1.5707949993 0 0" xyz="0 0 0" />
            <geometry>
                <cylinder length="0.03" radius="0.02" />
            </geometry>
            <material name="Blue" />
        </visual>
        <inertial>
            <mass value="1" />
            <inertia ixx="1.0" ixy="0.0" ixz="0.0" iyy="0.5" iyz="0.0" izz="1.0" />
        </inertial>
    </link>
    <joint name="joint6" type="revolute">
        <parent link="link5" />
        <child link="link6" />
        <origin rpy="0 0 0" xyz="0 0 0" />
        <axis xyz="0 0 1" />
        <limit effort="300" lower="-2.96" upper="2.96" velocity="1" />
        <dynamics damping="50" friction="1" />
    </joint>
    <!-- /////////////////////////////////////   LINK6  ////////////////////////////////////////////// -->
    <link name="link6">
        <visual>
            <origin rpy="0 1.5707949993 0" xyz="0 0 -0.02" />
            <geometry>
                <box size="0.04 0.02 0.02" />
            </geometry>
            <material name="Green" />
        </visual>
        <inertial>
            <mass value="1" />
            <inertia ixx="1.0" ixy="0.0" ixz="0.0" iyy="0.5" iyz="0.0" izz="1.0" />
        </inertial>
    </link>
    <transmission name="trans_joint1">
        <type>transmission_interface/SimpleTransmission</type>
        <joint name="joint1">
            <hardwareInterface>hardware_interface/EffortJointInterface</hardwareInterface>
        </joint>
        <actuator name="joint1_motor">
            <hardwareInterface>hardware_interface/EffortJointInterface</hardwareInterface>
            <mechanicalReduction>1</mechanicalReduction>
        </actuator>
    </transmission>
    <transmission name="trans_joint2">
        <type>transmission_interface/SimpleTransmission</type>
        <joint name="joint2">
            <hardwareInterface>hardware_interface/EffortJointInterface</hardwareInterface>
        </joint>
        <actuator name="joint2_motor">
            <hardwareInterface>hardware_interface/EffortJointInterface</hardwareInterface>
            <mechanicalReduction>1</mechanicalReduction>
        </actuator>
    </transmission>
    <transmission name="trans_joint3">
        <type>transmission_interface/SimpleTransmission</type>
        <joint name="joint3">
            <hardwareInterface>hardware_interface/EffortJointInterface</hardwareInterface>
        </joint>
        <actuator name="joint3_motor">
            <hardwareInterface>hardware_interface/EffortJointInterface</hardwareInterface>
            <mechanicalReduction>1</mechanicalReduction>
        </actuator>
    </transmission>
    <transmission name="trans_joint4">
        <type>transmission_interface/SimpleTransmission</type>
        <joint name="joint4">
            <hardwareInterface>hardware_interface/EffortJointInterface</hardwareInterface>
        </joint>
        <actuator name="joint4_motor">
            <hardwareInterface>hardware_interface/EffortJointInterface</hardwareInterface>
            <mechanicalReduction>1</mechanicalReduction>
        </actuator>
    </transmission>
    <transmission name="trans_joint5">
        <type>transmission_interface/SimpleTransmission</type>
        <joint name="joint5">
            <hardwareInterface>hardware_interface/EffortJointInterface</hardwareInterface>
        </joint>
        <actuator name="joint5_motor">
            <hardwareInterface>hardware_interface/EffortJointInterface</hardwareInterface>
            <mechanicalReduction>1</mechanicalReduction>
        </actuator>
    </transmission>
    <transmission name="trans_joint6">
        <type>transmission_interface/SimpleTransmission</type>
        <joint name="joint6">
            <hardwareInterface>hardware_interface/EffortJointInterface</hardwareInterface>
        </joint>
        <actuator name="joint6_motor">
            <hardwareInterface>hardware_interface/EffortJointInterface</hardwareInterface>
            <mechanicalReduction>1</mechanicalReduction>
        </actuator>
    </transmission>
    <gazebo>
        <plugin name="gazebo_ros_control">
            <robotNamespace>/</robotNamespace>
        </plugin>
    </gazebo>
</robot>

